Workbook

Sheet Summary
A1: ARCHEGON CAPITAL — PoC financial model. One page, then the evidence behind it.
A3: A pure venture opportunity starting from zero: buy the land, buy or contract the power, buy the compute, build the infrastructure, obtain the legals. Proof of concept in Australia and/or New Zealand.
A5: AT THE CURRENT CONTROL SETTINGS
A6: Route | B6: =Control!$B$4 | C6: Control switch.
A7: Compute model | B7: =Control!$B$5 | C7: Control switch.
A8: PoC capacity (MW critical IT) | B8: =Raise!$B$22 | C8: Control input, multiplied by sites funded. BOTH delivers two PoC sites.
A9: TOTAL RAISE (AUD) | B9: =Raise!$B$14 | C9: Derived on the Raise tab. A FLOOR — every RATE_MISSING line sits at zero.
A10: Total raise (USD) | B10: =Raise!$B$15 | C10: At the Rates FX.
A11: Raise per kW of critical IT (AUD) | B11: =Raise!$B$23
A12: Annual contribution once built and full (AUD) | B12: ='Compute-Revenue'!$B$31 | C12: Revenue less opex. Not EBITDA, not a return.
A13: Contribution as a share of the raise (3.3% at base: below any cost of capital) | B13: =IF('Compute-Revenue'!$B$31<=0,"n/a — contribution is not positive",B12/B9) | C13: The first ratio a VC computes. Against a raise that is itself a FLOOR — six RATE_MISSING lines sit at zero — and an opex line that is also a floor.
A14: Years of contribution to return the ask | B14: =Raise!$B$24 | C14: Not a payback period and not an IRR — no discounting, no ramp, no terminal value. State this number yourself before it is computed for you.
A16: THE TWO ROUTES, SIDE BY SIDE
A17: Australia — total capex (AUD) | B17: ='AU-Route'!$B$43 | C17: A DRILLING play. Cooper Basin EGS. Archegon owns the reservoir.
A18: Australia — wells in the programme | B18: ='AU-Route'!$B$10 | C18: Producers plus injectors, at the selected productivity case.
A19: New Zealand — total capex (NZD) | B19: ='NZ-Route'!$B$38 | C19: A CONTRACTING play. TVZ. Archegon owns a contract, not a reservoir.
A20: AU drilling spread, cheapest corner to dearest | B20: =Sensitivity!$B$15 | C20: Drilling alone, before a single server. The number to show first.
A22: HOW TO READ THIS WORKBOOK
A23: • Control is the only tab with switches. Change one and every number in the workbook moves.
A24: • Rates holds every sourced constant. The only unsourced figures are the Control inputs — capacity, contingency, runway, burn, capacity factor and PUE — each labelled ASSUMPTION where no finding exists.
A25: • Traceability maps each rate to the finding id in facts/ that produced it.
A26: • AU-Route and NZ-Route each carry four blocks: land, infrastructure, compute, legals.
A28: EVIDENCE QUALITY — stated up front, not buried
A29: Rates by status
A30: DERIVED | B30: =COUNTIF(Rates!$E$4:$E$90,$A30) | C30: Computed here from sourced inputs. The arithmetic is shown.
A31: INDICATIVE | B31: =COUNTIF(Rates!$E$4:$E$90,$A31) | C31: A single source, or a vendor figure, not independently confirmed.
A32: RATE_MISSING | B32: =COUNTIF(Rates!$E$4:$E$90,$A32) | C32: NO SOURCE EXISTS. Ships at zero. A gap in the evidence, not a zero-cost item.
A33: VERIFIED | B33: =COUNTIF(Rates!$E$4:$E$90,$A33) | C33: Traced to a primary source and checked by an independent verifier.
A34: VERIFIED-ESTIMATE | B34: =COUNTIF(Rates!$E$4:$E$90,$A34) | C34: Sourced, but the source is itself an estimate or a range.
A36: • v3: RATE_MISSING is counted by LINE on the route tabs (AU: 7 capex + 2 opex; NZ: 10), plus the new firm-power lines (BESS, standby, black start, hot-day derate, stimulation/test facilities). The rate-key tally above counts keys, not lines.
A37: • No rate in this workbook depends on a CONTESTED finding. That was checked at build time, not asserted.
A38: • This model produces no IRR and no NPV. An IRR built on RATE_MISSING blocks would be fiction with a decimal point on it — so the honest headline is the contribution-to-raise ratio above, stated plainly rather than omitted.
A40: • v2 (10 Oct 2026): added Funding-Tiers (A$50m-A$500m sizing from the same unit economics) and Deck-Check (deck figures vs live model). No input, rate or formula on the original nine tabs was changed.
A41: • v3 (12 Oct 2026): every point in the v3 review is tracked in CRITIQUE-TRACKER.md. New tabs: Definitions, Flow-Basis, Power-Economics, DC-Economics, Route-Compare, Firm-Power, Gated-Plan; Funding-Tiers rebuilt (whole modules, value optimiser). Headline reference raise unchanged at Control settings (Control BOTH now carries two teams).
A42: • Read first: contribution is 3.3% of the raise; the power system costs about what the hall earns; the first capital that retires the key risk is a ~A$52m reservoir test (Gated-Plan).
A44: RENTAL (colo) vs SELL COMPUTE (GPU-as-a-service), AU 5 MW reference: see Sell-Compute tab. PUBLIC PROXY inputs.
A45: Colo: total capital, A$ | B45: ='Sell-Compute'!$I$36
A46: Colo: annual contribution, A$ | B46: ='Sell-Compute'!$I$46
A47: Colo: 25-yr IRR | B47: ='Sell-Compute'!$I$51
A48: Compute: total capital incl. GPUs, A$ | B48: ='Sell-Compute'!$B$36
...

Sheet Control
A1: ARCHEGON CAPITAL · CONTROL — every switch that drives the model lives here
A3: Switch | B3: Setting | C3: What it does | D3: Allowed values
A4: Route | B4: AU | C4: Which route the Summary and Raise tabs report. Both route tabs always compute; this picks what rolls up. | D4: AU / NZ / BOTH
A5: Compute model | B5: COLO | C5: Revenue basis. COLO = sell space+power per kW. ANCHOR = long take-or-pay lease. BAREMETAL = own the GPUs, sell compute. | D5: COLO / ANCHOR / BAREMETAL
A6: Well productivity | B6: BASE | C6: MWe per production well. LOW = GeoExpro bear case (2 MWe). BASE = 4-6 MWe midpoint. HIGH = Fervo claim (10-16), unproven at scale. v3: all cases are NET MWe per producer at the plant fence (see Definitions); HIGH is a gross source figure used as an upper bound. | D6: LOW / BASE / HIGH
A7: Well cost case | B7: BASE | C7: AU drilling cost. LOW = best-case learning. BASE = engineered 5-well campaign. HIGH = single well, no campaign learning. ACTUAL = Habanero 4 as drilled. | D7: LOW / BASE / HIGH / ACTUAL
A8: Cooling | B8: LIQUID | C8: LIQUID applies the liquid-cooling premium. AIR does not. GB200-class density requires LIQUID. | D8: AIR / LIQUID
A9: Remote loading | B9: ON | C9: Applies the remote-site construction loading to the AU facility build. NZ sites are near existing infrastructure. | D9: ON / OFF
A11: Sizing and scenario inputs
A12: PoC capacity (MW critical IT) | B12: 5 | C12: Target compute load for the proof of concept.
A13: Contingency % | B13: 0.25 | C13: Applied to every capex block. A first-of-a-kind project.
A14: Operating runway (months) | B14: 24 | C14: Pre-revenue months the raise must fund.
A15: Team + overhead (AUD/month) | B15: 250000 | C15: Burn rate during the PoC. ASSUMPTION.
A16: Capacity factor | B16: 0.9 | C16: Average availability. Used to size NAMEPLATE (net) so ANNUAL energy matches the load. It is NOT a firm-power guarantee: see Firm-Power.
A17: Facility PUE (total facility power ÷ critical IT) | B17: 1.25 | C17: ASSUMPTION — no sourced finding exists for this in the evidence base. Liquid-cooled AI halls typically run 1.15-1.35. Critical IT is what is SOLD; PUE grosses it up to what the site must generate or buy. Set to 1.00 to reproduce the pre-review model. | D17: typically 1.15 - 1.35
A18: Sites funded (derived from Route) | B18: =IF($B$4="BOTH",2,1) | C18: Derived, not an input. BOTH builds a PoC on each route, so capacity, capex, revenue and opex all count twice. This cell is what keeps them consistent.
A21: Reading this model
A22: • Blue cells are inputs. Everything else is a formula — change an input and the whole model moves.
A23: • Every rate on the Rates tab names the finding it comes from and carries a status label.
A24: • RATE_MISSING rows ship at zero. They are gaps in the evidence base, not zero-cost items.
A25: • No figure in this workbook was typed from memory. Traceability maps every rate to a finding id.
A26: • Google Sheets: upload this .xlsx to Drive and Open with Google Sheets. Dropdowns and formulas transfer. Do not convert to a Google-native sheet that rewrites formulas. Blue cells stay the only inputs.

Sheet Definitions
A1: ARCHEGON · DEFINITIONS (v3): one meaning per word, used on every tab, slide, diagram and web page
A3: Gross (MW) | B3: Electrical output at the generator terminals, before the plant's own load.
A4: Parasitic load (MW) | B4: Power the plant uses itself: injection/reinjection pumps, ORC feed pumps, air-cooled condenser fans, plant services. For EGS, injection pumping dominates.
A5: Net (MW) | B5: Gross minus parasitic load = what the plant delivers to the site switchboard ("at the fence"). EVERY MWe-per-producer figure in this model is NET.
A6: Nameplate (MW, net) | B6: The net capacity the plant is built to deliver when running. AU-Route!B7 = IT x PUE / capacity factor = 6.94 MW.
A7: Average (MW) | B7: Nameplate x capacity factor (0.90) = 6.25 MW. This is an ANNUAL-ENERGY figure. It is what v2 wrongly called "firm".
A8: Firm (MW) | B8: Power guaranteed in every hour, including with the largest single element out (N-1: one producer, one ORC unit or one transformer). Today the design has NO firm figure above 5.0 MW (one producer out) and no backup: see Firm-Power.
A9: Facility load (MW) | B9: Critical IT x PUE. 5.0 MW IT x 1.25 = 6.25 MW.
A10: Critical IT (MW) | B10: Power to the racks. Sold in whole 1.25 MW modules (Rates module_mw_it).
A11: Contribution | B11: Revenue minus the opex lines in this model. NOT EBITDA, not a return, not a cash yield; excludes RATE_MISSING opex, financing, tax, ramp.
A12: Operating break-even hall | B12: The smallest build whose contribution is zero. v2 called this "minimum viable PoC"; it is NOT viable, it never returns capital.
A13: Reservoir-test tranche | B13: One doublet + rig mobilisation + contingency + runway, with no plant and no hall. Buys a 90-180 day circulation test (Gated-Plan).
A14: Transfer price | B14: The price at which PowerCo (wells + ORC) sells energy to DCCo (the hall). Set equal to PowerCo's levelised cost (Power-Economics) so each business stands on its own.
... A16: RATE_MISSING | B16: No source exists yet. Ships at A$0. The total is understated by that line.

Sheet Rates
A1: ARCHEGON CAPITAL · RATES — every constant, with its source finding and status label
A3: Key | B3: Rate | C3: Unit | D3: Value | E3: Status | F3: Finding id | G3: Note / what the status means
A4: fx_aud_usd | B4: AUD -> USD | C4: USD per AUD | D4: 0.7122 | E4: VERIFIED | F4: geothermal-capex-71 | G4: Restates USD benchmarks into AUD. Point-in-time rate.
A5: fx_aud_nzd | B5: AUD -> NZD | C5: NZD per AUD | D5: 1.2365 | E5: VERIFIED | F5: geothermal-capex-71 | G5: Implies 1 USD = 1.404 AUD and 1 USD = 1.736 NZD.
A6: au_well_cost_base | B6: Cooper Basin EGS well, engineered forward cost | C6: AUD/well | D6: 16500000 | E6: VERIFIED-ESTIMATE | F6: geothermal-capex-30 | G6: Geodynamics optimised slim-bore 5-well campaign average.
A7: au_well_cost_low | B7: Cooper Basin well, best case with high learning | C7: AUD/well | D7: 14000000 | E7: VERIFIED-ESTIMATE | F7: geothermal-capex-30 | G7: Best case in the same engineered estimate.
A8: au_well_cost_high | B8: Cooper Basin well, single-well (no campaign learning) | C8: AUD/well | D8: 22700000 | E8: VERIFIED-ESTIMATE | F8: geothermal-capex-30 | G8: One-off well; the cost if no campaign is assembled.
A9: au_well_actual_h4 | B9: Habanero 4 actual drilled cost | C9: AUD/well | D9: 50850000 | E9: VERIFIED | F9: geothermal-capex-29 | G9: The ANTI-learning curve: last well cost 4.5x the first.
A10: au_rig_day_rate | B10: Australian onshore rig day rate | C10: AUD/day | D10: 50000 | E10: VERIFIED | F10: geothermal-capex-31 | G10: Habanero field development plan assumption.
A11: au_rig_mob | B11: Rig mobilisation / demobilisation | C11: AUD | D11: 4000000 | E11: VERIFIED | F11: geothermal-capex-31 | G11: Single mob/demob for a Cooper Basin campaign.
A12: mwe_per_well_base | B12: MWe per producer - BASE (NET: at the plant fence, after plant parasitics; see Definitions) | C12: MWe | D12: 5 | E12: DERIVED | F12: geothermal-capex-15 | G12: DERIVED base case 4-6 MWe; midpoint used.
A13: mwe_per_well_low | B13: MWe per producer - LOW (NET: at the plant fence, after plant parasitics) | C13: MWe | D13: 2 | E13: DERIVED | F13: geothermal-capex-15 | G13: GeoExpro triplet-implied bear case.
A14: mwe_per_well_high | B14: MWe per producer - HIGH (source figure is GROSS; treated as NET here = optimistic upper bound) | C14: MWe | D14: 13 | E14: DERIVED | F14: geothermal-capex-15 | G14: Fervo claim 10-16 MWe per producer, quoted GROSS by the source. v3: the model has ONE convention (net at the fence). Using a gross figure as net overstates HIGH by the parasitic fraction (13.8%-29%, see rows 62-63). Kept only as an upper-bound sensitivity.
A15: plant_usd_per_kw | B15: 50 MW binary ORC plant, brownfield (wells already drilled) | C15: USD/kW | D15: 3963 | E15: VERIFIED | F15: geothermal-capex-16 | G15: EIA 2023 USD, USD 198.1m for 50 MW net.
... A43: dc_opex_usd_mw_yr | B43: Data centre non-energy opex (maintenance, insurance, security, connectivity, rates) | C43: USD/MW/yr | D43: 0 | E43: RATE_MISSING | F43: NO FINDING — gap raised in model review | G43: RATE_MISSING. Applies to BOTH routes. The evidence base covers data centre CAPEX benchmarks but carries no operating cost benchmark. Ships at zero, so the contribution line is an overstatement by exactly this amount.
A45: Status labels
A46: VERIFIED | B46: The figure appears in the cited source and an independent verifier confirmed it.
A47: VERIFIED-ESTIMATE | B47: Sourced, but the source itself presents it as an estimate or a range.
A48: DERIVED | B48: Arithmetic on sourced figures. The inputs are sourced; this number is not published.
A49: INDICATIVE | B49: A trade or market figure without a primary source behind it. Directionally useful only.
A50: CONTESTED | B50: An independent verifier raised a MAJOR against this figure. Do NOT present it as sourced.
A51: RATE_MISSING | B51: No published figure exists. Ships at zero. A gap in the evidence, not a zero cost.
A52: V3 ADDITIONS (12 Oct 2026): rates added to answer the v3 review
A53: hab_closed_loop_kg_s | B53: Habanero best sustained closed-loop circulation (2013, 160-day pilot) | C53: kg/s | D53: 19 | E53: INDICATIVE | F53: ThinkGeoEnergy 8 Oct 2013 | G53: Verify against the Geodynamics final reports before external use.
A54: hab_open_flow_kg_s | B54: Habanero 4 stabilised open-flow rate | C54: kg/s | D54: 39 | E54: INDICATIVE | F54: ThinkGeoEnergy | G54: 40-50 kg/s claimed at full drawdown.
A55: hab_wellhead_c | B55: Habanero 4 wellhead temperature, maximum | C55: degC | D55: 215 | E55: INDICATIVE | F55: ThinkGeoEnergy 2013
A56: red_flow_kg_s | B56: Fervo Project Red peak flow (63 L/s ~ 63 kg/s) | C56: kg/s | D56: 63 | E56: VERIFIED | F56: Norbeck & Latimer 2023 (EarthArXiv) | G56: Peak test, not sustained.
A57: red_peak_mwe | B57: Fervo Project Red peak electric equivalent | C57: MWe | D57: 3.5 | E57: VERIFIED | F57: Norbeck & Latimer 2023 | G57: Calculated electric equivalent, assumes supercritical ORC; not metered.
A58: red_temp_c | B58: Fervo Project Red production temperature (336 F) | C58: degC | D58: 169 | E58: VERIFIED | F58: Norbeck & Latimer 2023
A59: fervo_sust_flow_kg_s | B59: Fervo Project Red sustained average circulation (614+ days) | C59: kg/s | D59: 36 | E59: INDICATIVE | F59: Fervo operating update Apr 2026 | G59: Verify page reference.
A60: fervo_sust_gross_mw | B60: Fervo Project Red sustained average gross output | C60: MW | D60: 2.1 | E60: INDICATIVE | F60: Fervo operating update Apr 2026
A61: fervo_sust_net_mw | B61: Fervo Project Red sustained average net output | C61: MW | D61: 1.4 | E61: INDICATIVE | F61: Fervo operating update Apr 2026; deck slide 5
A62: parasitic_eia | B62: Parasitic load, conventional binary plant (EIA Case 11: ~58 MW gross for 50 MW net) | C62: share of gross | D62: 0.138 | E62: VERIFIED | F62: EIA capital cost study (geothermal-capex-16)
A63: geoexpro_pump_mw | B63: Cape Station test: injection pumping estimate | C63: MW | D63: 2.5 | E63: INDICATIVE | F63: GeoExpro, Yearsley & Kombrink, 1 Oct 2025 | G63: Critic estimate, not company data.
A64: geoexpro_gross_mw | B64: Cape Station test: gross output estimate | C64: MW | D64: 8.7 | E64: INDICATIVE | F64: GeoExpro, 1 Oct 2025
A65: parasitic_egs_stress | B65: EGS parasitic stress case = pumping / gross | C65: share of gross | D65: =D63/D64 | E65: DERIVED | F65: Arithmetic on rows 63-64 | G65: Replaces the unsourced "Fervo ~33%" used in v2. Use as stress, not as a Cooper Basin prediction.
A66: cp_water | B66: Specific heat of hot water (constant-cp approximation) | C66: kJ/kg.K | D66: 4.2 | E66: ASSUMPTION | F66: Physics approximation | G66: Used only on Flow-Basis.
A67: dead_state_c | B67: Dead-state (ambient) temperature for exergy | C67: degC | D67: 25 | E67: ASSUMPTION | F67: Archegon screening method
A68: exergy_util_low | B68: Share of brine exergy converted to gross power - low | C68: share | D68: 0.4 | E68: ASSUMPTION | F68: Archegon screening method | G68: Project Red back-calculates to ~50% (Flow-Basis).
A69: exergy_util_high | B69: Share of brine exergy converted to gross power - high | C69: share | D69: 0.5 | E69: ASSUMPTION | F69: Archegon screening method
...

Sheet AU-Route
A1: ARCHEGON CAPITAL · AUSTRALIA — Cooper Basin EGS. Buy the land, drill the wells, build the plant, build the hall.
A3: Australia is a drilling play. The heat is there and measured; the permeability is not. That is what the capital buys.
A5: RESOURCE SIZING | F5: drives well count
A6: Net MWe per producer (scenario; NET at the plant fence) | B6: =IF(Control!$B$6="LOW",Rates!$D$13,IF(Control!$B$6="HIGH",Rates!$D$14,Rates!$D$12)) | C6: LOW = GeoExpro bear case. HIGH = Fervo claim, unproven at fleet scale.
A7: Net generation nameplate required (MW, after parasitics) | B7: =Control!$B$12*Control!$B$17/Control!$B$16 | C7: Critical IT x PUE / capacity factor. NET nameplate: what the plant must deliver to the site board after its own parasitic load (injection pumps, ORC feed pumps, condenser fans, plant services). Matches the EIA per-NET-kW plant rate. Delivers 6.25 MW on AVERAGE, not firm (see Firm-Power).
A8: Production wells required | B8: =ROUNDUP(B7/B6,0) | C8: Rounded up — you cannot drill a partial well.
A9: Injection wells required | B9: =B8 | C9: Doublet architecture: one injector per producer. Fervo runs this pattern.
A10: TOTAL wells | B10: =B8+B9
A12: BLOCK 1 — LAND | F12: AUD
A13: Surface land / pastoral lease access | B13: 0 | C13: RATE_MISSING. Pastoral lease over the Cooper Basin footprint. Lessee and compensation regime not yet established — see legals-land open questions.
A14: Site preparation and access roads | B14: 0 | C14: RATE_MISSING. Remote site; no public benchmark located.
A15: Land subtotal | B15: =SUM(B13:B14) | C15: Both lines are RATE_MISSING. This block is UNDERSTATED, not cheap.
A17: BLOCK 2 — INFRASTRUCTURE (subsurface + surface plant) | F17: AUD
A18: Cost per well (scenario) | B18: =IF(Control!$B$7="LOW",Rates!$D$7,IF(Control!$B$7="HIGH",Rates!$D$8,IF(Control!$B$7="ACTUAL",Rates!$D$9,Rates!$D$6))) | C18: BASE is Geodynamics' engineered forward estimate, never realised. ACTUAL is Habanero 4 as drilled — 4.5x the first well. Run ACTUAL before believing BASE.
A19: Drilling programme | B19: =B18*B10 | C19: The single largest line in the Australian route.
A20: Rig mobilisation / demobilisation | B20: =Rates!$D$11 | C20: One mob/demob per campaign. Fixed regardless of well count.
A21: Binary ORC surface plant | B21: =Rates!$D$15/Rates!$D$4*B7*1000 | C21: EIA 50 MW brownfield cost, converted at the Rates FX. Brownfield = wells already drilled, which is why drilling sits on its own line above.
A22: Brine gathering, heat exchange, pipework | B22: 0 | C22: RATE_MISSING. Geodynamics' AUD 182m stack had this at ~14% of non-well cost; not carried forward as a rate because the scope differs.
A23: Infrastructure subtotal (incl. stimulation, Rates D78) | B23: =SUM(B19:B22)+Rates!$D$78
A25: BLOCK 3 — COMPUTE (the hall and the silicon) | F25: AUD
A26: Data centre shell and core | B26: =Rates!$D$21/Rates!$D$4*Control!$B$12 | C26: Per MW of critical IT load.
A27: Liquid cooling premium | B27: =IF(Control!$B$8="LIQUID",Rates!$D$22/Rates!$D$4*Control!$B$12,0) | C27: GB200-class density requires liquid. AIR is modelled only for contrast.
A28: Remote-site loading | B28: =IF(Control!$B$9="ON",(B26+B27)*(Rates!$D$24-1),0) | C28: Innamincka is ~820 km straight-line from Adelaide (Rates km_innamincka_adelaide); road distance is longer. Prefab assumed.
A29: Long-haul fibre / connectivity | B29: 0 | C29: RATE_MISSING. No public per-km figure for a Moomba-Adelaide route was located. Carrier availability is itself an open question, not just a price.
A30: IT fit-out incl. GPUs (BAREMETAL only) | B30: =IF(Control!$B$5="BAREMETAL",Rates!$D$28/Rates!$D$4*Control!$B$12,0) | C30: JLL's US$25m/MW covers GPUs, networking AND racks in one figure — so there is no separate GPU line to add. In COLO and ANCHOR the TENANT pays this, not Archegon. This single toggle decides what kind of company Archegon is: landlord or owner-operator. VCs price those as different companies.
A31: Compute subtotal | B31: =SUM(B26:B30)
A32: cross-check: racks x rack price (NOT added) | B32: =ROUNDDOWN(Control!$B$12*1000/Rates!$D$27,0)*Rates!$D$26/Rates!$D$4 | C32: v3: racks ROUNDED DOWN (power-limited hall: 5,000 kW / 130 kW = 38 complete racks). Bottom-up cross-check, NOT added.
A34: BLOCK 4 — LEGALS | F34: AUD
A35: Native title agreement | B35: =Rates!$D$38 | C35: RATE_MISSING. Determination SCD2015/003 already exists and names the RNTBC, so the counterparty is known. The open question is whether a geothermal licence can enjoin the existing petroleum conjunctive ILUA (SI2006/008).
A36: Aboriginal heritage clearance | B36: =Rates!$D$39 | C36: RATE_MISSING. A SEPARATE statute from native title (Aboriginal Heritage Act 1988 SA). Routinely collapsed into native title in pitch material; it is not.
A37: Tenement, environmental and EPBC | B37: =Rates!$D$40 | C37: RATE_MISSING. Energy Resources Act 2000 (SA) licence plus any EPBC referral.
A38: Legals subtotal | B38: =SUM(B35:B37) | C38: ENTIRE BLOCK IS RATE_MISSING. No published cost exists for concluding an SA native title agreement (legals-08). Requires a counsel quote before use.
A40: AUSTRALIAN ROUTE — TOTAL CAPEX | F40: AUD
A41: Sum of the four blocks | B41: =B15+B23+B31+B38 | C41: Land + infrastructure + compute + legals.
A42: Contingency | B42: =B41*Control!$B$13 | C42: First-of-a-kind in this basin. Habanero's own history argues for more, not less.
A43: TOTAL AU CAPEX | B43: =B41+B42
A44: Implied AUD/kW — GENERATION only | B44: =(B15+B23)*(1+Control!$B$13)/(B7*1000) | C44: Wells and plant over gross generation capacity. THIS is the line to compare against Habanero actual AUD 23,600/kW. The comparator excludes the data centre, so this figure must too.
A45: Implied AUD/kW — ALL-IN over critical IT | B45: =B43/(Control!$B$12*1000) | C45: Everything, over the MW of compute actually sold. A data centre metric, not a geothermal one — do not compare it to a per-kW generation benchmark.
A47: What this total does NOT include
A48: • Every RATE_MISSING line above — land, fibre, brine gathering and the whole legals block.
...

Sheet NZ-Route
A1: ARCHEGON CAPITAL · NEW ZEALAND — Taupo Volcanic Zone. Contract the power, build the hall. No drilling risk.
A3: New Zealand is a contracting play. The TVZ is conventional hydrothermal and already in commercial production — Contact, Mercury, Eastland and Top Energy own it. Archegon does not drill here; it contracts.
A5: RESOURCE — CONTRACTED, NOT DRILLED
A6: Gross generation required (MW) | B6: =Control!$B$12*Control!$B$17/Control!$B$16 | C6: Same grossing-up as Australia — PUE then capacity factor. The difference is who owns the wells.
A7: Wells drilled by Archegon | B7: 0 | C7: Zero. This is the whole point of the NZ route: the drilling risk sits with an incumbent who has already taken it.
A8: Reference NZ greenfield cost NOT incurred (NZD) | B8: =Rates!$D$17*B6*1000 | C8: Shown to size what contracting avoids — it is NOT a cost in this route. It is the capital an incumbent already sank.
A10: BLOCK 1 — LAND | F10: NZD
A11: Site lease / land acquisition | B11: 0 | C11: RATE_MISSING. TVZ land is frequently Maori freehold or under iwi/hapu interest. The counterparty on every TVZ project is an iwi or hapu entity.
A12: Site preparation | B12: 0 | C12: RATE_MISSING.
A13: Land subtotal | B13: =SUM(B11:B12)
A15: BLOCK 2 — INFRASTRUCTURE (connection, not drilling) | F15: NZD
A16: Behind-the-meter connection and substation | B16: 0 | C16: RATE_MISSING. A data centre is a LOAD connection — expressly handled outside Transpower's generation Connection Management Framework, so the CMF fee is NOT the entry ticket here.
A17: Fibre and connectivity | B17: 0 | C17: RATE_MISSING. Materially easier than Cooper Basin — TVZ sites sit near existing routes — but no figure is carried.
A18: Infrastructure subtotal | B18: =SUM(B16:B17)
A20: BLOCK 3 — COMPUTE (the hall and what goes in it) | F20: NZD
A21: Data centre shell and power train | B21: =Rates!$D$21*Control!$B$12*(Rates!$D$5/Rates!$D$4) | C21: USD/MW benchmark converted at Rates FX. No remote loading: TVZ sites are 1-3 hours from Auckland/Tauranga, not ~820 km straight-line (Rates) from Adelaide.
A22: Liquid cooling premium | B22: =IF(Control!$B$8="LIQUID",Rates!$D$22*Control!$B$12*(Rates!$D$5/Rates!$D$4),0) | C22: Toggled on Control!Cooling. INDICATIVE rate.
A23: Fibre and connectivity | B23: 0 | C23: RATE_MISSING.
A24: IT fit-out incl. GPUs (BAREMETAL only) | B24: =IF(Control!$B$5="BAREMETAL",Rates!$D$28*Control!$B$12*(Rates!$D$5/Rates!$D$4),0) | C24: One figure covering GPUs, networking and racks - there is no separate GPU line to add. Zero under COLO and ANCHOR: the tenant brings the silicon.
A25: Compute subtotal | B25: =SUM(B21:B24)
A26: cross-check: racks x rack price (NOT added) | B26: =ROUNDDOWN(Control!$B$12*1000/Rates!$D$27,0)*Rates!$D$26*(Rates!$D$5/Rates!$D$4) | C26: Bottom-up from GB200 rack economics. Outside the subtotal on purpose.
A28: BLOCK 4 — LEGALS AND CONSENTING | F28: NZD
A29: Resource consents (RMA) and planning | B29: =Rates!$D$41 | C29: RATE_MISSING (v3: now LINKED to Rates!D41, so pricing NZ consenting on Rates flows through).
A30: Iwi / hapu engagement and agreements | B30: 0 | C30: RATE_MISSING. Not a box to tick. On TVZ land the iwi entity is frequently the landowner, the Treaty partner and a potential equity party at once.
A31: Overseas Investment Act screening | B31: 0 | C31: RATE_MISSING. An offshore-funded acquirer of sensitive land triggers OIO consent; source page for decision timelines returns 404 (nz-route-44).
A32: Power purchase agreement negotiation | B32: 0 | C32: RATE_MISSING. This is the NZ route's real gate - a firm, long-dated, behind-the-meter PPA with an incumbent generator.
A33: Legals subtotal | B33: =SUM(B29:B32) | C33: ENTIRE BLOCK IS RATE_MISSING. Requires NZ counsel quotes before use.
A35: NEW ZEALAND ROUTE — TOTAL CAPEX | F35: NZD
A36: Sum of the four blocks | B36: =B13+B18+B25+B33 | C36: Land + infrastructure + compute + legals. Note what is absent: wells.
A37: Contingency | B37: =B36*Control!$B$13 | C37: Lower subsurface risk than AU, but the same first-of-a-kind build risk.
A38: TOTAL NZ CAPEX | B38: =B36+B37
A39: Implied NZD/kW — ALL-IN over critical IT | B39: =B38/(Control!$B$12*1000) | C39: There is no generation-only figure on this route because Archegon builds no generation. Do NOT compare this to a per-kW geothermal benchmark — it is a data centre number.
A41: CONTRACTED POWER — the cost that replaces the wells | F41: NZD/yr
A42: Annual energy consumed (MWh) | B42: =Control!$B$12*Control!$B$17*8760 | C42: Total facility load (critical IT x PUE) running continuously. The hall draws 8,760 hours a year regardless of generator availability, so the capacity factor does NOT belong in this line — it sizes plant, not consumption.
A43: Indicative annual power cost | B43: =B42*Rates!$D$35 | C43: At the NZ wholesale benchmark. A real behind-the-meter geothermal PPA is negotiated, not screen-priced - this line sizes the opex, it does not quote it.
A45: Why the NZ route is the faster PoC, and why it is also the weaker moat
A46: • FASTER: the resource already exists and is in commercial production. No drilling risk, no dry hole, no stimulation programme, no 6-month native title minimum.
A47: • WEAKER: what Archegon owns is a contract, not a reservoir. The incumbent can decline to renew, or price the renewal against the tenant's switching cost.
A48: • The AU route is the reverse trade: worse schedule, harder capital, an owned asset.

Sheet Compute-Revenue
A1: ARCHEGON CAPITAL · COMPUTE AND REVENUE — three ways to sell the same megawatt. Reported in AUD.
A3: v3: Slide 11's "energy is ~7% of AI-DC TCO" describes a GPU OWNER. Under COLO Archegon owns the shell and the power system, and the power system costs about as much as the hall earns (Power-Economics). The premium for firm, carbon-free power is UNPROVEN until tenant LOIs price it.
A5: SOLD CAPACITY
A6: Critical IT sold (kW) | B6: =Control!$B$12*1000 | C6: Assumes the PoC sells out. A ramp belongs in a later version.
A7: Energy delivered (MWh/yr) | B7: =Control!$B$12*Control!$B$17*8760 | C7: Total facility energy: critical IT x PUE, running continuously. The capacity factor sizes generation, not consumption, so it is deliberately absent here.
A9: MODEL A — COLOCATION (sell space and power per kW/month) | F9: AUD/yr
A10: Colocation revenue | B10: =B6*Rates!$D$29*12*(1/Rates!$D$4) | C10: AU market rate. Sydney trades higher; the Sydney rate is on Rates as the upper reference. VERIFIED-ESTIMATE.
A12: MODEL B — ANCHOR LEASE (one take-or-pay tenant) | F12: AUD/yr
A13: Anchor lease revenue | B13: =Rates!$D$31*Control!$B$12*(1/Rates!$D$4) | C13: DERIVED per-MW lease. The alternative benchmark on Rates is ~23% lower — run both before quoting either.
A15: MODEL C — BARE METAL (own the GPUs, sell compute) | F15: AUD/yr
A16: Bare-metal compute revenue | B16: 0 | C16: RATE_MISSING BY DELIBERATE CHOICE. The GPU-hour rates that would drive this line were demoted to CONTESTED — an independent verifier could not locate them in any cited source. Quoting a GPU-hour price here would be inventing the single number a VC checks first.
A17: Power-only fallback, AU route (islanded: no grid connection) | B17: 0 | C17: v3 FIX: v2 linked Rates!D33, which equals the colo rate, so the "fallback" was colo revenue relabelled. With no grid connection an unsold AU megawatt earns nothing. Real fallback options (grid export, curtailable flexible load) are priced on Power-Economics; the connection cost is RATE_MISSING.
A18: Illustrative grid-export value IF a connection existed (SA wholesale, not contracted) | B18: ='Power-Economics'!$B$33 | C18: Wholesale x net average MWh. Connection capex RATE_MISSING. Not in contribution.
A19: SELECTED REVENUE (follows Control!Compute model) | F19: AUD/yr
A20: Revenue on the selected model | B20: =IF(Control!$B$5="COLO",B10,IF(Control!$B$5="ANCHOR",B13,B16))*Control!$B$18 | C20: Per-site revenue multiplied by Control!Sites funded, so BOTH sells two sites' worth. BAREMETAL resolves to zero on purpose — see Model C.
A22: OPERATING COST — differs by route, because ownership differs | F22: AUD/yr
A23: AU: geothermal plant fixed O&M | B23: =Rates!$D$16*'AU-Route'!$B$7*1000*(1/Rates!$D$4) | C23: Archegon OWNS the plant on the AU route, so it carries the O&M. Applied to GROSS generation capacity, not critical IT.
A24: NZ: contracted power purchase | B24: ='NZ-Route'!$B$42*Rates!$D$35*(1/Rates!$D$5) | C24: Archegon BUYS power on the NZ route, so it carries an energy bill instead of an O&M bill. Screen price, not a negotiated PPA.
A25: AU: make-up / well replacement provision | B25: =IF(Control!$B$4="NZ",0,Rates!$D$42) | C25: RATE_MISSING, ships at zero. The plant O&M rate above EXCLUDES well replacement, so without this line the AU route silently assumes the reservoir never declines. NZ's opex rate already includes make-up drilling — that asymmetry is why this line exists.
A26: Both routes: data centre non-energy opex | B26: =Rates!$D$43*Control!$B$12*Control!$B$18*(1/Rates!$D$4) | C26: RATE_MISSING, ships at zero. Maintenance, insurance, security, connectivity and rates. The evidence base carries data centre capex benchmarks but no opex benchmark, so contribution below is overstated by exactly this amount.
A27: Team and overhead (per site funded) | B27: =Control!$B$15*12*Control!$B$18 | C27: v3: multiplied by sites funded. BOTH no longer assumes one team runs two routes; shared overhead needs a resource-loaded plan first.
A28: Opex on the selected route | B28: =IF(Control!$B$4="NZ",B24,IF(Control!$B$4="BOTH",B23+B24,B23))+B25+B26+B27 | C28: BOTH carries both routes' energy/O&M — running two routes costs two routes. Two of the five lines above are RATE_MISSING, so this is a FLOOR on opex, not an estimate.
A30: CONTRIBUTION | F30: AUD/yr
A31: Revenue less opex | B31: =B20-B28 | C31: Pre-financing, pre-tax, pre-depreciation. This is NOT EBITDA and NOT a return — it is the annual cash the PoC throws off once built and full.
A33: What this tab deliberately does not do
A34: • No ramp. Revenue is shown at full occupancy from year one — a PoC will not do that.
A35: • No escalation, no discounting, no terminal value. There is no IRR in this workbook because an IRR built on RATE_MISSING blocks would be fiction with a decimal point.
A36: • Parasitic load is not netted off saleable capacity. PUE is now applied — that covers cooling and facility overhead — but the generator's own consumption (EIA 13.8% vs Fervo actual ~33%) is a separate, unresolved gross-up that moves the AU well count.
A37: • Opex is a FLOOR. Two of the five cost lines above are RATE_MISSING and ship at zero: AU well replacement and data centre non-energy opex. Contribution is overstated by whatever those two turn out to be.

Sheet Raise
A1: ARCHEGON CAPITAL · THE RAISE — derived from the cost stack, not chosen and back-filled
A3: Nothing on this tab is a round number picked first. The ask is the sum of the four money blocks on the selected route, plus the runway needed to reach them. Change a Control switch and the ask moves.
A5: CAPEX ON THE SELECTED ROUTE | F5: AUD
A6: Australian route capex | B6: ='AU-Route'!$B$43 | C6: From AU-Route. Buy the land, drill the wells, build the plant, build the hall.
A7: New Zealand route capex (converted to AUD) | B7: ='NZ-Route'!$B$38*(1/Rates!$D$5) | C7: From NZ-Route at the Rates cross-rate. No drilling in this figure.
A8: Capex to fund | B8: =IF(Control!$B$4="NZ",B7,IF(Control!$B$4="BOTH",B6+B7,B6)) | C8: BOTH funds two routes in parallel — the optionality is real and so is the bill.
A10: PRE-REVENUE OPERATING RUNWAY | F10: AUD
A11: Team and overhead through the runway | B11: =Control!$B$15*Control!$B$14*Control!$B$18 | C11: v3: x sites funded (BOTH = two teams). ASSUMPTION rate.
A13: THE ASK | F13: AUD
A14: TOTAL RAISE (derived) | B14: =B8+B11 | C14: Capex on the selected route plus the runway to deliver it.
A15: Total raise (USD) | B15: =B14*Rates!$D$4 | C15: At the Rates FX. For a USD-denominated conversation.
A17: USE OF FUNDS (share of the derived ask) | F17: %
A18: Capex share of the ask | B18: =B8/B14 | C18: How much of the raise becomes an asset.
A19: Runway share of the ask | B19: =B11/B14 | C19: How much of the raise is burn. A high number here is a red flag to a VC.
A21: WHAT THE ASK BUYS
A22: Critical IT delivered (MW) | B22: =Control!$B$12*Control!$B$18 | C22: From Control, multiplied by sites funded. BOTH delivers two PoC sites, so the denominator below doubles with the numerator.
A23: Raise per kW of critical IT | B23: =B14/(B22*1000) | C23: The number a data centre investor will compute in their head. Compare against the shell and fit-out benchmarks on Rates. Critical IT sold — the site generates PUE times this.
A24: Years of contribution to equal the ask (undiscounted) | B24: =IF('Compute-Revenue'!$B$31<=0,"n/a — contribution is not positive",B14/'Compute-Revenue'!$B$31) | C24: NOT an IRR and NOT a payback period — no discounting, no ramp, no terminal value. A magnitude check only.
A26: What this ask does NOT cover — say this before a VC finds it
A27: • Every RATE_MISSING line. Land, fibre, brine gathering, the entire AU legals block and the entire NZ legals block ship at zero in capex — and AU well replacement and data centre operating cost ship at zero in opex. The ask is a FLOOR, not an estimate.
A28: • No dry-hole or under-performing-well allowance on the AU route. EGS fails continuously — the failure mode is a reservoir that produces 60% of plan, not a hole with no heat.
A29: • No second tranche. A PoC that works needs production capital that this ask does not raise.
A30: • No allowance for the 6-month statutory minimum on the AU native title path (legals-01) running long. Schedule risk is not costed here.

Sheet Sensitivity
A1: ARCHEGON CAPITAL · SENSITIVITY — the three source conflicts that move the answer most
A3: These are not made-up scenarios. Each row is a live disagreement between sources in facts/ — the model carries both ends rather than picking one and hiding the other.
A5: Driver | B5: Low | C5: Base | D5: High | E5: Actual | F5: Why the sources disagree | G5: Control switch
A6: MWe per production well | B6: =Rates!$D$13 | C6: =Rates!$D$12 | D6: =Rates!$D$14 | E6: n/a | F6: GeoExpro reads ~2 MWe from operating EGS. Fervo claims 10-16. A 6.5x spread on the single input that sets how many wells you drill. | G6: Well productivity
A7: Cost per well (AUD) | B7: =Rates!$D$7 | C7: =Rates!$D$6 | D7: =Rates!$D$8 | E7: =Rates!$D$9 | F7: LOW/BASE/HIGH are all Geodynamics engineered forward estimates — best case, campaign average and single-well. ACTUAL is Habanero 4 as drilled, 4.5x the first well. The learning curve ran backwards. | G7: Well cost case
A9: AU WELL PROGRAMME AT EACH CORNER (live) | G9: Drilling capex only
A10: Productivity \ well cost | B10: LOW cost | C10: BASE cost | D10: HIGH cost | E10: ACTUAL (Habanero 4)
A11: LOW (2 MWe) | B11: =('AU-Route'!$B$10/'AU-Route'!$B$8)*ROUNDUP((Control!$B$12*Control!$B$17/Control!$B$16)/Rates!$D$13,0)*B$7 | C11: =('AU-Route'!$B$10/'AU-Route'!$B$8)*ROUNDUP((Control!$B$12*Control!$B$17/Control!$B$16)/Rates!$D$13,0)*C$7 | D11: =('AU-Route'!$B$10/'AU-Route'!$B$8)*ROUNDUP((Control!$B$12*Control!$B$17/Control!$B$16)/Rates!$D$13,0)*D$7 | E11: =('AU-Route'!$B$10/'AU-Route'!$B$8)*ROUNDUP((Control!$B$12*Control!$B$17/Control!$B$16)/Rates!$D$13,0)*E$7
A12: BASE (5 MWe) | B12: =('AU-Route'!$B$10/'AU-Route'!$B$8)*ROUNDUP((Control!$B$12*Control!$B$17/Control!$B$16)/Rates!$D$12,0)*B$7 | C12: =('AU-Route'!$B$10/'AU-Route'!$B$8)*ROUNDUP((Control!$B$12*Control!$B$17/Control!$B$16)/Rates!$D$12,0)*C$7 | D12: =('AU-Route'!$B$10/'AU-Route'!$B$8)*ROUNDUP((Control!$B$12*Control!$B$17/Control!$B$16)/Rates!$D$12,0)*D$7 | E12: =('AU-Route'!$B$10/'AU-Route'!$B$8)*ROUNDUP((Control!$B$12*Control!$B$17/Control!$B$16)/Rates!$D$12,0)*E$7
A13: HIGH (13 MWe) | B13: =('AU-Route'!$B$10/'AU-Route'!$B$8)*ROUNDUP((Control!$B$12*Control!$B$17/Control!$B$16)/Rates!$D$14,0)*B$7 | C13: =('AU-Route'!$B$10/'AU-Route'!$B$8)*ROUNDUP((Control!$B$12*Control!$B$17/Control!$B$16)/Rates!$D$14,0)*C$7 | D13: =('AU-Route'!$B$10/'AU-Route'!$B$8)*ROUNDUP((Control!$B$12*Control!$B$17/Control!$B$16)/Rates!$D$14,0)*D$7 | E13: =('AU-Route'!$B$10/'AU-Route'!$B$8)*ROUNDUP((Control!$B$12*Control!$B$17/Control!$B$16)/Rates!$D$14,0)*E$7
A15: Spread, cheapest corner to dearest | B15: =MAX(B11:E13)/MIN(B11:E13) | C15: The ratio a VC should be shown first. Drilling alone, before a single server is bought. Now spans all four cost cases including Habanero 4 as drilled.
A17: CONFLICTS THE MODEL CANNOT RESOLVE
A18: Parasitic load: 13.8% (EIA, conventional) vs ~29% (EGS stress, GeoExpro-derived: 2.5 MW pumping / 8.7 MW gross)
A19: v3: well ratings are NET by definition (Definitions), so parasitic is inside the rating. Flow-Basis shows what that requires in kg/s, and how many producers a gross-only rating would need.
A21: Capex per kW (US$): Habanero 16,808 at model FX (23,600 x 0.7122) vs Fervo 7,000 (overnight, first project) -> 5,500 (Phase II all-in, expected) -> 3,000 (target)
A22: v3: Fervo US$7,000/kW is in the S-1/A filed 4 May 2026 as an OVERNIGHT cost for the first Cape Station project: CONTESTED cleared, mis-date (31 Dec 2025) corrected. The three Fervo figures are on different bases and are shown as separate points, not a curve. At model FX Habanero is 2.4x Fervo's first-project figure. The model uses none of them as an input.
A24: Every RATE_MISSING block
A25: Land, fibre, brine gathering, AU legals, NZ legals. Four counsel quotes and two engineering quotes would close most of this. None exists yet.
A27: Plant scale penalty (sensitivity, ASSUMPTION 0.6 exponent from the 50 MW EIA reference)
A28: Per-kW multiplier at net nameplate | B28: =(50/'AU-Route'!$B$7)^(1-Rates!$D$81)
A29: AU raise with scale penalty | B29: =Raise!$B$14+'AU-Route'!$B$21*(B28-1)*(1+Control!$B$13)
A30: AU raise with scale penalty AND remote loading on the plant | B30: =Raise!$B$14+'AU-Route'!$B$21*(B28*Rates!$D$24-1)*(1+Control!$B$13)
A31: AU raise at HIGH (single-well, first-of-a-kind) well cost | B31: =Raise!$B$14+'AU-Route'!$B$10*(Rates!$D$8-'AU-Route'!$B$18)*(1+Control!$B$13)

Sheet Traceability
A1: ARCHEGON CAPITAL · TRACEABILITY — every rate in this workbook, and the finding it came from
A3: No figure in this workbook was typed from memory. Each row below names the finding id in facts/ that a rate came from, the status that finding carries, and the claim as recorded. A rate whose finding is missing stops the build.
A5: Rate key | B5: Rate | C5: Value | D5: Unit | E5: Status | F5: Finding id and claim | G5: Why this rate, and what it does not cover
A6: fx_aud_usd | B6: AUD -> USD | C6: 0.7122 | D6: USD per AUD | E6: VERIFIED | F6: geothermal-capex-71 — Exchange rates for restating USD geothermal capex figures into Australian and New Zealand dollars | G6: Restates USD benchmarks into AUD. Point-in-time rate.
A7: fx_aud_nzd | B7: AUD -> NZD | C7: 1.2365 | D7: NZD per AUD | E7: VERIFIED | F7: geothermal-capex-71 — Exchange rates for restating USD geothermal capex figures into Australian and New Zealand dollars | G7: Implies 1 USD = 1.404 AUD and 1 USD = 1.736 NZD.
A8: au_well_cost_base | B8: Cooper Basin EGS well, engineered forward cost | C8: 16500000 | D8: AUD/well | E8: VERIFIED-ESTIMATE | F8: geothermal-capex-30 — Geodynamics' engineered forward cost estimate for Cooper Basin EGS wells under an optimised slim-bore design and campaign drilling - the Australian 'if we did it again' number | G8: Geodynamics optimised slim-bore 5-well campaign average.
A9: au_well_cost_low | B9: Cooper Basin well, best case with high learning | C9: 14000000 | D9: AUD/well | E9: VERIFIED-ESTIMATE | F9: geothermal-capex-30 — Geodynamics' engineered forward cost estimate for Cooper Basin EGS wells under an optimised slim-bore design and campaign drilling - the Australian 'if we did it again' number | G9: Best case in the same engineered estimate.
A10: au_well_cost_high | B10: Cooper Basin well, single-well (no campaign learning) | C10: 22700000 | D10: AUD/well | E10: VERIFIED-ESTIMATE | F10: geothermal-capex-30 — Geodynamics' engineered forward cost estimate for Cooper Basin EGS wells under an optimised slim-bore design and campaign drilling - the Australian 'if we did it again' number | G10: One-off well; the cost if no campaign is assembled.
A11: au_well_actual_h4 | B11: Habanero 4 actual drilled cost | C11: 50850000 | D11: AUD/well | E11: VERIFIED | F11: geothermal-capex-29 — Actual drilled cost and duration of every deep EGS well in the Cooper Basin, Australia (Geodynamics, Habanero/Jolokia) - the only Australian deep-EGS well cost record that exists | G11: The ANTI-learning curve: last well cost 4.5x the first.
A12: au_rig_day_rate | B12: Australian onshore rig day rate | C12: 50000 | D12: AUD/day | E12: VERIFIED | F12: geothermal-capex-31 — Australian onshore drilling rig day rate and mobilisation cost assumed in the Habanero field development plan for a 750,000 lb rated rig | G12: Habanero field development plan assumption.
A13: au_rig_mob | B13: Rig mobilisation / demobilisation | C13: 4000000 | D13: AUD | E13: VERIFIED | F13: geothermal-capex-31 — Australian onshore drilling rig day rate and mobilisation cost assumed in the Habanero field development plan for a 750,000 lb rated rig | G13: Single mob/demob for a Cooper Basin campaign.
A14: mwe_per_well_base | B14: Net MWe per production well - BASE | C14: 5 | D14: MWe | E14: DERIVED | F14: geothermal-capex-15 — Base case recommended for MWe per production well and per doublet in an Archegon financial model, reconciling company and critic sources | G14: DERIVED base case 4-6 MWe; midpoint used.
A15: mwe_per_well_low | B15: Net MWe per production well - LOW | C15: 2 | D15: MWe | E15: DERIVED | F15: geothermal-capex-15 — Base case recommended for MWe per production well and per doublet in an Archegon financial model, reconciling company and critic sources | G15: GeoExpro triplet-implied bear case.
A16: mwe_per_well_high | B16: Gross MWe per producer - HIGH | C16: 13 | D16: MWe | E16: DERIVED | F16: geothermal-capex-15 — Base case recommended for MWe per production well and per doublet in an Archegon financial model, reconciling company and critic sources | G16: Fervo claim 10-16 MWe; midpoint. Unproven at fleet scale.
A17: plant_usd_per_kw | B17: 50 MW binary ORC plant, brownfield (wells already drilled) | C17: 3963 | D17: USD/kW | E17: VERIFIED | F17: geothermal-capex-16 — All-in capital cost of a 50 MW net binary-cycle (ORC) geothermal power plant on a BROWNFIELD site where production and injection wells are already drilled - i.e. surface plant plus gathering system only, no drilling | G17: EIA 2023 USD, USD 198.1m for 50 MW net.
... A45: dc_opex_usd_mw_yr | B45: Data centre non-energy opex (maintenance, insurance, security, connectivity, rates) | C45: 0 | D45: USD/MW/yr | E45: RATE_MISSING | F45: NO FINDING — gap raised in model review. The evidence base carries data centre capex benchmarks only. | G45: RATE_MISSING. Applies to both routes. Ships at zero, so contribution is overstated by exactly this amount.
A47: Status tally
A48: DERIVED | B48: =COUNTIF($E$6:$E$45,$A48)
A49: INDICATIVE | B49: =COUNTIF($E$6:$E$45,$A49)
A50: RATE_MISSING | B50: =COUNTIF($E$6:$E$45,$A50)
A51: VERIFIED | B51: =COUNTIF($E$6:$E$45,$A51)
A52: VERIFIED-ESTIMATE | B52: =COUNTIF($E$6:$E$45,$A52)

Sheet Deck-Check
A1: ARCHEGON CAPITAL · DECK CHECK: every model-derived figure on the master deck, against the live model
A3: Deck v1 (23 Sep 2026) was built from the model with PUE = 1.00. Setting Control!B17 to 1.00 and recalculating reproduces every v1 figure exactly (column E). Deck v2 shows the model at PUE 1.25 (column D). Column G turns FALSE if a Control change moves the model away from what deck v2 displays.
A5: Slide | B5: Figure | C5: Deck v1 shows | D5: Deck v2 shows | E5: Model at PUE 1.00 (recalculated 10 Oct 2026) | F5: Live model value | G5: Deck v2 = live? (to displayed precision) | H5: Model cell
A6: 12 | B6: Net nameplate MW (plant fence) | C6: 5.56 | D6: 6.94 | E6: 5.5556 | F6: ='AU-Route'!B7 | G6: =ROUND(F6,2)=ROUND(D6,2) | H6: AU-Route!B7
A7: 12 | B7: Total wells | C7: 4 | D7: 4 | E7: 4 | F7: ='AU-Route'!B10 | G7: =ROUND(F7,0)=ROUND(D7,0) | H7: AU-Route!B10
A8: 12 | B8: AU infra (wells+mob+plant), A$m | C8: 100.9 | D8: 108.6 | E8: 100.9136 | F8: ='AU-Route'!B23/1000000 | G8: =ROUND(F8,1)=ROUND(D8,1) | H8: AU-Route!B23
A9: 12 | B9: AU compute, A$m | C9: 132.3 | D9: 132.3 | E9: 132.3364 | F9: ='AU-Route'!B31/1000000 | G9: =ROUND(F9,1)=ROUND(D9,1) | H9: AU-Route!B31
A10: 12 | B10: AU contingency, A$m (chart) | C10: 58.3 | D10: 60.2 | E10: 58.3125 | F10: ='AU-Route'!B42/1000000 | G10: =ROUND(F10,1)=ROUND(D10,1) | H10: AU-Route!B42
A11: 12 | B11: AU floor (total capex), A$m | C11: 291.6 | D11: 301.2 | E11: 291.5625 | F11: ='AU-Route'!B43/1000000 | G11: =ROUND(F11,1)=ROUND(D11,1) | H11: AU-Route!B43
A12: 12 | B12: NZ floor, A$m | C12: 127.3 | D12: 127.2 | E12: 127.2466 | F12: =Raise!B7/1000000 | G12: =ROUND(F12,1)=ROUND(D12,1) | H12: Raise!B7
A13: 12 | B13: NZ stack, NZ$m | C13: 157.3 | D13: 157.3 | E13: 157.3404 | F13: ='NZ-Route'!B38/1000000 | G13: =ROUND(F13,1)=ROUND(D13,1) | H13: NZ-Route!B38
A14: 12 | B14: NZ compute (chart), A$m | C14: 101.8 | D14: 101.8 | E14: 101.7976 | F14: ='NZ-Route'!B25/Rates!D5/1000000 | G14: =ROUND(F14,1)=ROUND(D14,1) | H14: NZ-Route!B25
A15: 12 | B15: NZ contingency (chart), A$m | C15: 25.5 | D15: 25.4 | E15: 25.4493 | F15: ='NZ-Route'!B37/Rates!D5/1000000 | G15: =ROUND(F15,1)=ROUND(D15,1) | H15: NZ-Route!B37
A16: 13 | B16: AU route capex, A$m | C16: 291.6 | D16: 301.2 | E16: 291.5625 | F16: =Raise!B8/1000000 | G16: =ROUND(F16,1)=ROUND(D16,1) | H16: Raise!B8
A17: 13 | B17: Runway, A$m | C17: 6 | D17: 6 | E17: 6 | F17: =Raise!B11/1000000 | G17: =ROUND(F17,1)=ROUND(D17,1) | H17: Raise!B11
A18: 13 | B18: Derived raise, A$m | C18: 297.6 | D18: 307.2 | E18: 297.5625 | F18: =Raise!B14/1000000 | G18: =ROUND(F18,1)=ROUND(D18,1) | H18: Raise!B14
A19: 13 | B19: Derived raise, US$m | C19: 211.9 | D19: 218.8 | E19: 211.924 | F19: =Raise!B15/1000000 | G19: =ROUND(F19,1)=ROUND(D19,1) | H19: Raise!B15
A20: 14 | B20: COLO revenue, A$m/yr | C20: 14.5 | D20: 14.5 | E20: 14.5324 | F20: ='Compute-Revenue'!B10/1000000 | G20: =ROUND(F20,1)=ROUND(D20,1) | H20: Compute-Revenue!B10
A21: 14 | B21: ANCHOR revenue, A$m/yr | C21: 16.6 | D21: 16.6 | E21: 16.6386 | F21: ='Compute-Revenue'!B13/1000000 | G21: =ROUND(F21,1)=ROUND(D21,1) | H21: Compute-Revenue!B13
A22: 14 | B22: Opex (plant O&M + team), A$m/yr | C22: 4.2 | D22: 4.5 | E22: 4.1748 | F22: ='Compute-Revenue'!B28/1000000 | G22: =ROUND(F22,1)=ROUND(D22,1) | H22: Compute-Revenue!B28
A23: 14 | B23: COLO contribution, A$m/yr | C23: 10.4 | D23: 10.1 | E23: 10.3577 | F23: ='Compute-Revenue'!B31/1000000 | G23: =ROUND(F23,1)=ROUND(D23,1) | H23: Compute-Revenue!B31
A25: NZ: v1 showed the NZ floor as A$127.3m and NZ contingency as A$25.5m. The model gives A$127.25m and A$25.45m, which round to A$127.2m and A$25.4m. v1 was a rounding error that does not depend on PUE, and v2 corrects it. Rounding note: slide 12 chart labels sum to A$301.1m (108.6 + 132.3 + 60.2) against a A$301.2m total. Each label is the model value rounded on its own. v1 had the same effect: its chart total read A$291.5m against a A$291.6m header. v2 stores unrounded values, so the chart total now reads A$301.2m.
A26: Slide 14: A$14.5m − A$4.5m appears to give A$10.0m, but the model gives A$10.06m (14.532 − 4.468). The displayed values are each rounded to 0.1.
A30: v3: deck slide numbers follow archegon-deck-v3.pptx; new slides 17-22 draw on Definitions, Flow-Basis, Power-Economics, Route-Compare, Firm-Power, Gated-Plan.

Sheet Flow-Basis
A1: ARCHEGON · FLOW BASIS: what flow per producer does 5 MWe NET need, and what has the Cooper Basin delivered?
A3: Method (ASSUMPTION, Archegon screening): net MW = flow x specific exergy of hot water x utilisation x (1 - parasitic). Specific exergy e = cp[(T-T0) - (T0+273.15) ln((T+273.15)/(T0+273.15))]. This is a screening calculation, NOT a reservoir forecast. It does not replace a reservoir engineer's sustainable rate, temperature and injectivity case, which the founder must supply (status: NEEDS DATA).
A5: Inputs (linked to Rates)
A6: cp (kJ/kg.K) | B6: =Rates!$D$66
A7: Dead state T0 (degC) | B7: =Rates!$D$67
A8: Utilisation low | B8: =Rates!$D$68
A9: Utilisation high | B9: =Rates!$D$69
A10: Parasitic low (EIA) | B10: =Rates!$D$62
A11: Parasitic high (EGS stress, GeoExpro-derived) | B11: =Rates!$D$65
A12: Target NET MWe per producer (scenario) | B12: ='AU-Route'!$B$6
A14: A. Flow needed per producer for the target NET MWe
A15: Production temperature (degC) | B15: Specific exergy (kJ/kg) | C15: Flow needed, optimistic (kg/s): util high, parasitic low | D15: Flow needed, conservative (kg/s): util low, parasitic high | E15: Reference
A16: =Rates!$D$58 | B16: =$B$6*((A16)-$B$7-($B$7+273.15)*LN(((A16)+273.15)/($B$7+273.15))) | C16: =$B$12*1000/(B16*$B$9*(1-$B$10)) | D16: =$B$12*1000/(B16*$B$8*(1-$B$11)) | E16: Fervo Project Red
A17: 200 | B17: =$B$6*((A17)-$B$7-($B$7+273.15)*LN(((A17)+273.15)/($B$7+273.15))) | C17: =$B$12*1000/(B17*$B$9*(1-$B$10)) | D17: =$B$12*1000/(B17*$B$8*(1-$B$11)) | E17: Habanero earlier trial (~200 degC)
A18: =Rates!$D$55 | B18: =$B$6*((A18)-$B$7-($B$7+273.15)*LN(((A18)+273.15)/($B$7+273.15))) | C18: =$B$12*1000/(B18*$B$9*(1-$B$10)) | D18: =$B$12*1000/(B18*$B$8*(1-$B$11)) | E18: Habanero 4 wellhead, 2013
A19: 220 | B19: =$B$6*((A19)-$B$7-($B$7+273.15)*LN(((A19)+273.15)/($B$7+273.15))) | C19: =$B$12*1000/(B19*$B$9*(1-$B$10)) | D19: =$B$12*1000/(B19*$B$8*(1-$B$11))
A20: 240 | B20: =$B$6*((A20)-$B$7-($B$7+273.15)*LN(((A20)+273.15)/($B$7+273.15))) | C20: =$B$12*1000/(B20*$B$9*(1-$B$10)) | D20: =$B$12*1000/(B20*$B$8*(1-$B$11))
A22: B. What measured flows would deliver (NET MWe per producer, at Habanero 215 degC)
A23: Flow (kg/s) | B23: Source | C23: NET MWe, optimistic | D23: NET MWe, conservative | E23: vs target (conservative)
A24: =Rates!$D$53 | B24: Habanero best sustained closed loop (INDICATIVE) | C24: =A24*$B$18*$B$9*(1-$B$10)/1000 | D24: =A24*$B$18*$B$8*(1-$B$11)/1000 | E24: =D24/$B$12
A25: =Rates!$D$54 | B25: Habanero 4 open flow (INDICATIVE) | C25: =A25*$B$18*$B$9*(1-$B$10)/1000 | D25: =A25*$B$18*$B$8*(1-$B$11)/1000 | E25: =D25/$B$12
A26: =Rates!$D$59 | B26: Fervo Red sustained average (INDICATIVE) | C26: =A26*$B$18*$B$9*(1-$B$10)/1000 | D26: =A26*$B$18*$B$8*(1-$B$11)/1000 | E26: =D26/$B$12
A27: =Rates!$D$56 | B27: Fervo Red peak (VERIFIED) | C27: =A27*$B$18*$B$9*(1-$B$10)/1000 | D27: =A27*$B$18*$B$8*(1-$B$11)/1000 | E27: =D27/$B$12
A28: 107 | B28: Fervo Cape 30-day max, Sep 2024 | C28: =A28*$B$18*$B$9*(1-$B$10)/1000 | D28: =A28*$B$18*$B$8*(1-$B$11)/1000 | E28: =D28/$B$12
A30: C. Calibration and slide 5 reconciliation
A31: Project Red implied utilisation (3.5 MWe from 63 kg/s at 169 degC, treated as gross) | B31: =Rates!$D$57*1000/(Rates!$D$56*B16) | C31: ~50% = top of the range: consistent with a calculated, not metered, figure.
A32: Fervo sustained: NET / GROSS | B32: =Rates!$D$61/Rates!$D$60 | C32: 1.4 / 2.1: parasitic ~33% of gross.
A33: Slide 5 step 1: Project Red PEAK (MWe) | B33: =Rates!$D$57 | C33: Peak
A34: Slide 5 step 2: sustained GROSS (MW) | B34: =Rates!$D$60 | C34: Sustained average over 614+ days
A35: Slide 5 step 3: parasitic (MW) | B35: =Rates!$D$60-Rates!$D$61
A36: Slide 5 step 4: sustained NET (MW) | B36: =Rates!$D$61 | C36: v2 implied 3.5 x (1-33%) = 1.4, which is wrong (= 2.35). 1.4 is 2.1 gross less 0.7 parasitic.
A37: Linear scale-up: flow for 5 MWe NET at Fervo sustained ratio (kg/s) | B37: =Rates!$D$59*$B$12/Rates!$D$61 | C37: Illustration (~129 kg/s). Not linear in reality.
A39: D. Sensitivity: MWe per producer -> wells and AU raise (other inputs at Control settings)
A40: NET MWe per producer | B40: Basis | C40: Producers (N+0) | D40: Total wells (doublets) | E40: AU raise, A$ (doublets) | F40: Total wells (triplets: 2 injectors per producer) | G40: AU raise, A$ (triplets) | H40: Contribution / raise (doublets)
A41: =Rates!$D$61 | B41: Fervo sustained net (slide 5 underwriting figure) | C41: =ROUNDUP(ROUND('AU-Route'!$B$7/A41,6),0) | D41: =2*C41 | E41: =(D41*'AU-Route'!$B$18+('AU-Route'!$B$20+'AU-Route'!$B$21+'AU-Route'!$B$22+'AU-Route'!$B$15+'AU-Route'!$B$31+'AU-Route'!$B$38))*(1+Control!$B$13)+Raise!$B$11 | F41: =3*C41 | G41: =(F41*'AU-Route'!$B$18+('AU-Route'!$B$20+'AU-Route'!$B$21+'AU-Route'!$B$22+'AU-Route'!$B$15+'AU-Route'!$B$31+'AU-Route'!$B$38))*(1+Control!$B$13)+Raise!$B$11 | H41: ='Compute-Revenue'!$B$31/E41
A42: =D24 | B42: Habanero 19 kg/s, conservative conversion | C42: =ROUNDUP(ROUND('AU-Route'!$B$7/A42,6),0) | D42: =2*C42 | E42: =(D42*'AU-Route'!$B$18+('AU-Route'!$B$20+'AU-Route'!$B$21+'AU-Route'!$B$22+'AU-Route'!$B$15+'AU-Route'!$B$31+'AU-Route'!$B$38))*(1+Control!$B$13)+Raise!$B$11 | F42: =3*C42 | G42: =(F42*'AU-Route'!$B$18+('AU-Route'!$B$20+'AU-Route'!$B$21+'AU-Route'!$B$22+'AU-Route'!$B$15+'AU-Route'!$B$31+'AU-Route'!$B$38))*(1+Control!$B$13)+Raise!$B$11 | H42: ='Compute-Revenue'!$B$31/E42
A43: =C24 | B43: Habanero 19 kg/s, optimistic conversion | C43: =ROUNDUP(ROUND('AU-Route'!$B$7/A43,6),0) | D43: =2*C43 | E43: =(D43*'AU-Route'!$B$18+('AU-Route'!$B$20+'AU-Route'!$B$21+'AU-Route'!$B$22+'AU-Route'!$B$15+'AU-Route'!$B$31+'AU-Route'!$B$38))*(1+Control!$B$13)+Raise!$B$11 | F43: =3*C43 | G43: =(F43*'AU-Route'!$B$18+('AU-Route'!$B$20+'AU-Route'!$B$21+'AU-Route'!$B$22+'AU-Route'!$B$15+'AU-Route'!$B$31+'AU-Route'!$B$38))*(1+Control!$B$13)+Raise!$B$11 | H43: ='Compute-Revenue'!$B$31/E43
A44: =Rates!$D$13 | B44: Model LOW | C44: =ROUNDUP(ROUND('AU-Route'!$B$7/A44,6),0) | D44: =2*C44 | E44: =(D44*'AU-Route'!$B$18+('AU-Route'!$B$20+'AU-Route'!$B$21+'AU-Route'!$B$22+'AU-Route'!$B$15+'AU-Route'!$B$31+'AU-Route'!$B$38))*(1+Control!$B$13)+Raise!$B$11 | F44: =3*C44 | G44: =(F44*'AU-Route'!$B$18+('AU-Route'!$B$20+'AU-Route'!$B$21+'AU-Route'!$B$22+'AU-Route'!$B$15+'AU-Route'!$B$31+'AU-Route'!$B$38))*(1+Control!$B$13)+Raise!$B$11 | H44: ='Compute-Revenue'!$B$31/E44
A45: ='AU-Route'!$B$7/2 | B45: Threshold where 2 producers just cover nameplate | C45: =ROUNDUP(ROUND('AU-Route'!$B$7/A45,6),0) | D45: =2*C45 | E45: =(D45*'AU-Route'!$B$18+('AU-Route'!$B$20+'AU-Route'!$B$21+'AU-Route'!$B$22+'AU-Route'!$B$15+'AU-Route'!$B$31+'AU-Route'!$B$38))*(1+Control!$B$13)+Raise!$B$11 | F45: =3*C45 | G45: =(F45*'AU-Route'!$B$18+('AU-Route'!$B$20+'AU-Route'!$B$21+'AU-Route'!$B$22+'AU-Route'!$B$15+'AU-Route'!$B$31+'AU-Route'!$B$38))*(1+Control!$B$13)+Raise!$B$11 | H45: ='Compute-Revenue'!$B$31/E45
A46: =Rates!$D$12 | B46: Model BASE | C46: =ROUNDUP(ROUND('AU-Route'!$B$7/A46,6),0) | D46: =2*C46 | E46: =(D46*'AU-Route'!$B$18+('AU-Route'!$B$20+'AU-Route'!$B$21+'AU-Route'!$B$22+'AU-Route'!$B$15+'AU-Route'!$B$31+'AU-Route'!$B$38))*(1+Control!$B$13)+Raise!$B$11 | F46: =3*C46 | G46: =(F46*'AU-Route'!$B$18+('AU-Route'!$B$20+'AU-Route'!$B$21+'AU-Route'!$B$22+'AU-Route'!$B$15+'AU-Route'!$B$31+'AU-Route'!$B$38))*(1+Control!$B$13)+Raise!$B$11 | H46: ='Compute-Revenue'!$B$31/E46
...

Sheet Power-Economics
A1: ARCHEGON · POWER ECONOMICS (PowerCo: wells + ORC, AU route), priced as electricity, separate from the hall
A3: Both reviews asked for two businesses with two P&Ls. PowerCo owns wells and plant and sells energy to DCCo at a TRANSFER PRICE = its levelised cost. WACC and life are ASSUMPTIONS (Rates).
A5: Generation asset
A6: Generation capex pre-contingency (wells + mob + ORC + brine gathering), A$ | B6: ='AU-Route'!$B$23 | C6: AU-Route B23
A7: Generation capex incl. contingency, A$ | B7: =B6*(1+Control!$B$13)
A8: Net nameplate (MW) | B8: ='AU-Route'!$B$7 | C8: NET (Definitions)
A9: Average net delivered (MW) | B9: =B8*Control!$B$16 | C9: Average, NOT firm
A10: Annual energy (MWh) | B10: =B9*8760 | C10: Facility load x 8760 h
A11: Plant fixed O&M, A$/yr | B11: ='Compute-Revenue'!$B$23 | C11: Excludes well replacement (RATE_MISSING)
A13: Levelised cost of energy (LCOE) = (capex x CRF + O&M) / MWh
A14: Case | B14: Discount rate | C14: Life (yrs) | D14: CRF | E14: LCOE A$/MWh | F14: Capital + O&M, A$/yr
A15: Low | B15: =0.06 | C15: =Rates!$D$71 | D15: =B15/(1-(1+B15)^(-C15)) | E15: =F15/$B$10 | F15: =$B$7*D15+$B$11
A16: BASE (Rates wacc_base) | B16: =Rates!$D$70 | C16: =Rates!$D$71 | D16: =B16/(1-(1+B16)^(-C16)) | E16: =F16/$B$10 | F16: =$B$7*D16+$B$11
A17: High | B17: =0.10 | C17: =Rates!$D$71 | D17: =B17/(1-(1+B17)^(-C17)) | E17: =F17/$B$10 | F17: =$B$7*D17+$B$11
